Workbook
Name AA: #REF!
Name AA: #REF!
Name AA: #REF!
Name aaa: #REF!
Name bu: #REF!
Name bu: #REF!
Name bu: #REF!
Name cenarios: #REF!
Name CSM: #REF!
Name CSM: #REF!
Name CSM: #REF!
Name CUSTOS3: #REF!
Name CUSTOS3: #REF!
Name CUSTOS3: #REF!
Name DATA_QI: #REF!
Name DATA_QI: #REF!
Name DATA_QI: #REF!
Name fe: #REF!
Name fe: #REF!
Name fe: #REF!
Name fgts: #REF!
Name fgts: #REF!
Name fgts: #REF!
Name fgts2: #REF!
Name fgts2: #REF!
Name fgts2: #REF!
Name Início_do_projeto: #REF!
Name Início_do_projeto: #REF!
Name Início_do_projeto: #REF!
Name MAC: #REF!
Name MAC: #REF!
Name MAC: #REF!
Name oo: #REF!
Name oo: #REF!
Name oo: #REF!
Name PIPELINE: #REF!
Name PIPELINE: #REF!
Name PIPELINE: #REF!
Name PIPELINE2: #REF!
Name PIPELINE2: #REF!
Name PIPELINE2: #REF!
Name possibilidades: #REF!
Name PROBABILIDADE: #REF!
Name PROBABILIDADE: #REF!
Name PROBABILIDADE: #REF!
Name PROBABILIDADE2: #REF!
Name PROBABILIDADE2: #REF!
Name PROBABILIDADE2: #REF!
Name Semana_de_exibição: #REF!
Name Semana_de_exibição: #REF!
Name Semana_de_exibição: #REF!
Name TP_FLUXO: #REF!
Name TP_FLUXO: #REF!
Name TP_FLUXO: #REF!
Name TP_FLUXO2: #REF!
Name TP_FLUXO2: #REF!
Name TP_FLUXO2: #REF!
Name XX: #REF!
Name XX: #REF!
Name XX: #REF!

Sheet Sumário

Sheet Estrutura_Mínima_BEP
B1: Data de atualização: | H1: 45903
B2: Documentos originais utilizados para atualização: | H2: 202508_Maclinea_Reorganization_Analysis_Provisório_3_v2
A4: 9 | F4: =F105 -> -1362955 | H4: =H105 -> 83819.757 | K4: =K105 -> -122417.79
F5: Custo estrutura (sem faturamento) | H5: Peças/Service + Máquinas Selecionadas | I5: % RL | K5: Somente Peças/Service | L5: % RL | N5: Origem
A7: 0.075 | C7: Receita Bruta | F7: =SUM(F8:F11) -> 0 | H7: =SUM(H8:H11) -> 2171500 | I7: =H7/H$19 -> 1.2355489 | K7: =SUM(K8:K11) -> 850000 | L7: =K7/K$19 -> 1.2804194 | N7: Premissas_Receita!A1
D8: Service | H8: =SUMIFS(Premissas_Receita!I:I,Premissas_Receita!A:A,Estrutura_Mínima_BEP!D8) -> 150000 | K8: =H8 -> 150000
D9: Peças | H9: =SUMIFS(Premissas_Receita!I:I,Premissas_Receita!A:A,Estrutura_Mínima_BEP!D9) -> 700000 | K9: =H9 -> 700000
D10: Máquinas Pequenas | H10: =SUMIFS(Premissas_Receita!I:I,Premissas_Receita!A:A,Estrutura_Mínima_BEP!D10) -> 365833.33
D11: Máquinas Grandes | H11: =SUMIFS(Premissas_Receita!I:I,Premissas_Receita!A:A,Estrutura_Mínima_BEP!D11) -> 955666.67
C13: Impostos Indiretos | F13: =SUM(F14:F17) -> 0 | H13: =SUM(H14:H17) -> 413981.6 | I13: =H13/H$19 -> 0.23554894 | K13: =SUM(K14:K17) -> 186155 | L13: =K13/K$19 -> 0.28041938 | N13: Premissas_Receita!A1
D14: Service | H14: =SUMIFS(Premissas_Receita!I:I,Premissas_Receita!A:A,Estrutura_Mínima_BEP!D14)*VLOOKUP(Estrutura_Mínima_BEP!D14,Premissas_Receita!A:J,10,0) -> 21375 | I14: =H14/H8 -> 0.1425 | K14: =H14 -> 21375 | L14: =K14/K8 -> 0.1425
D15: Peças | H15: =SUMIFS(Premissas_Receita!I:I,Premissas_Receita!A:A,Estrutura_Mínima_BEP!D15)*VLOOKUP(Estrutura_Mínima_BEP!D15,Premissas_Receita!A:J,10,0) -> 164780 | I15: =H15/H9 -> 0.2354 | K15: =H15 -> 164780 | L15: =K15/K9 -> 0.2354
A16: =F16/F6 -> #DIV/0! | D16: Máquinas Pequenas | H16: =SUMIFS(Premissas_Receita!I:I,Premissas_Receita!A:A,Estrutura_Mínima_BEP!D16)*VLOOKUP(Estrutura_Mínima_BEP!D16,Premissas_Receita!A:J,10,0) -> 63069.667 | I16: =H16/H10 -> 0.1724 | L16: =K16/K10 -> #DIV/0!
A17: =F17/F7 -> #DIV/0! | D17: Máquinas Grandes | H17: =SUMIFS(Premissas_Receita!I:I,Premissas_Receita!A:A,Estrutura_Mínima_BEP!D17)*VLOOKUP(Estrutura_Mínima_BEP!D17,Premissas_Receita!A:J,10,0) -> 164756.93 | I17: =H17/H11 -> 0.1724 | L17: =K17/K11 -> #DIV/0!
C19: Receita Líquida | F19: =SUM(F20:F23) -> 0 | H19: =SUM(H20:H23) -> 1757518.4 | I19: =H19/H$19 -> 1 | K19: =SUM(K20:K23) -> 663845 | L19: =K19/K$19 -> 1
D20: Service | H20: =H8-H14 -> 128625 | I20: =H20/$K$8 -> 0.8575 | K20: =H20 -> 128625 | L20: =K20/$K$8 -> 0.8575
D21: Peças | H21: =H9-H15 -> 535220 | I21: =H21/$K$9 -> 0.7646 | K21: =H21 -> 535220 | L21: =K21/$K$9 -> 0.7646
A22: =F22/F12 -> #DIV/0! | D22: Máquinas Pequenas | H22: =H10-H16 -> 302763.67 | I22: =H22/$K$19 -> 0.45607584 | L22: =K22/$K$19 -> 0
A23: =F23/F13 -> #DIV/0! | D23: Máquinas Grandes | H23: =H11-H17 -> 790909.73 | I23: =H23/$K$19 -> 1.1914072 | L23: =K23/$K$19 -> 0
C25: Comissão | F25: =SUM(F26:F29) -> 0 | H25: =SUM(H26:H29) -> 60658.275 | I25: =H25/H$19 -> 0.034513593 | K25: =SUM(K26:K29) -> 5974.605 | L25: =K25/K$19 -> 0.009 | N25: Premissas_Receita!A1
D26: Service | H26: =SUMIFS(Premissas_Receita!M:M,Premissas_Receita!A:A,Estrutura_Mínima_BEP!D26) -> 1157.625 | I26: =H26/$H20 -> 0.009 | K26: =H26 -> 1157.625 | L26: =K26/$H20 -> 0.009
D27: Peças | H27: =SUMIFS(Premissas_Receita!M:M,Premissas_Receita!A:A,Estrutura_Mínima_BEP!D27) -> 4816.98 | I27: =H27/$H21 -> 0.009 | K27: =H27 -> 4816.98 | L27: =K27/$H21 -> 0.009
A28: =F28/F19 -> #DIV/0! | D28: Máquinas Pequenas | H28: =SUMIFS(Premissas_Receita!M:M,Premissas_Receita!A:A,Estrutura_Mínima_BEP!D28) -> 15138.183 | I28: =H28/$H22 -> 0.05 | L28: =K28/$H22 -> 0
A29: =F29/F20 -> #DIV/0! | D29: Máquinas Grandes | H29: =SUMIFS(Premissas_Receita!M:M,Premissas_Receita!A:A,Estrutura_Mínima_BEP!D29) -> 39545.487 | I29: =H29/$H23 -> 0.05 | L29: =K29/$H23 -> 0
C31: Material | F31: =SUM(F32:F35) -> 0 | H31: =SUM(H32:H35) -> 897206.96 | I31: =H31/H$19 -> 0.51049648 | K31: =SUM(K32:K35) -> 328686 | L31: =K31/K$19 -> 0.49512461 | N31: Premissas_Receita!A1
D32: Service | H32: =SUMIFS(Premissas_Receita!O:O,Premissas_Receita!A:A,Estrutura_Mínima_BEP!D32) -> 0 | I32: =H32/$H20 -> 0 | K32: =H32 -> 0 | L32: =K32/$H20 -> 0
D33: Peças | H33: =SUMIFS(Premissas_Receita!O:O,Premissas_Receita!A:A,Estrutura_Mínima_BEP!D33) -> 328686 | I33: =H33/$H21 -> 0.61411382 | K33: =H33 -> 328686 | L33: =K33/$H21 -> 0.61411382
A34: =F34/F25 -> #DIV/0! | D34: Máquinas Pequenas | H34: =SUMIFS(Premissas_Receita!O:O,Premissas_Receita!A:A,Estrutura_Mínima_BEP!D34) -> 171918.06 | I34: =H34/$H22 -> 0.56782924 | L34: =K34/$H22 -> 0
A35: =F35/F26 -> #DIV/0! | D35: Máquinas Grandes | H35: =SUMIFS(Premissas_Receita!O:O,Premissas_Receita!A:A,Estrutura_Mínima_BEP!D35) -> 396602.9 | I35: =H35/$H23 -> 0.50145154 | L35: =K35/$H23 -> 0
C37: 1a Margem | H37: =SUM(H38:H41) -> 799653.16 | I37: =H37/H$19 -> 0.45498992 | K37: =SUM(K38:K41) -> 329184.4 | L37: =K37/K$19 -> 0.49587539
D38: Service | H38: =H20-H26-H32 -> 127467.38 | I38: =H38/H20 -> 0.991 | K38: =K20-K26-K32 -> 127467.38 | L38: =K38/K20 -> 0.991
D39: Peças | H39: =H21-H27-H33 -> 201717.02 | I39: =H39/H21 -> 0.37688618 | K39: =K21-K27-K33 -> 201717.02 | L39: =K39/K21 -> 0.37688618
A40: =F40/F31 -> #DIV/0! | D40: Máquinas Pequenas | H40: =H22-H28-H34 -> 115707.42 | I40: =H40/H22 -> 0.38217076 | L40: =K40/K22 -> #DIV/0!
A41: =F41/F32 -> #DIV/0! | D41: Máquinas Grandes | H41: =H23-H29-H35 -> 354761.35 | I41: =H41/H23 -> 0.44854846 | L41: =K41/K23 -> #DIV/0!
C43: Custo Fixo | F43: =F44+F56+F70+F80+F90 -> 1362955 | H43: =H44+H56+H70+H80+H90 -> 715833.41 | I43: =H43/H$19 -> 0.40729782 | K43: =K44+K56+K70+K80+K90 -> 451602.19 | L43: =K43/K$19 -> 0.68028258
D44: Custo de Pessoal | F44: =SUM(F45:F54) -> 1022332.3 | H44: =SUM(H45:H54) -> 458211.92 | I44: =H44/H$19 -> 0.26071529 | K44: =SUM(K45:K54) -> 301399.04 | L44: =K44/K$19 -> 0.4540202 | N44: Análise_Rescisões_Estrutura!A1
E45: ADM | F45: 255459.91 | H45: =SUMIFS(Análise_Rescisões_Estrutura!I:I,Análise_Rescisões_Estrutura!E:E,Estrutura_Mínima_BEP!E45,Análise_Rescisões_Estrutura!G:G,FALSE) -> 93830.735 | K45: =SUMIFS(Análise_Rescisões_Estrutura!I:I,Análise_Rescisões_Estrutura!E:E,Estrutura_Mínima_BEP!E45,Análise_Rescisões_Estrutura!H:H,FALSE) -> 93830.735
E46: ADM Produção | F46: 102758.41 | H46: =SUMIFS(Análise_Rescisões_Estrutura!I:I,Análise_Rescisões_Estrutura!E:E,Estrutura_Mínima_BEP!E46,Análise_Rescisões_Estrutura!G:G,FALSE) -> 36189.867 | K46: =SUMIFS(Análise_Rescisões_Estrutura!I:I,Análise_Rescisões_Estrutura!E:E,Estrutura_Mínima_BEP!E46,Análise_Rescisões_Estrutura!H:H,FALSE) -> 36189.867
E47: Almoxarifado | F47: 22791.386 | H47: =SUMIFS(Análise_Rescisões_Estrutura!I:I,Análise_Rescisões_Estrutura!E:E,Estrutura_Mínima_BEP!E47,Análise_Rescisões_Estrutura!G:G,FALSE) -> 5278.2793 | K47: =SUMIFS(Análise_Rescisões_Estrutura!I:I,Análise_Rescisões_Estrutura!E:E,Estrutura_Mínima_BEP!E47,Análise_Rescisões_Estrutura!H:H,FALSE) -> 5278.2793
E48: Assist.Tecnica | F48: 179000.89 | H48: =SUMIFS(Análise_Rescisões_Estrutura!I:I,Análise_Rescisões_Estrutura!E:E,Estrutura_Mínima_BEP!E48,Análise_Rescisões_Estrutura!G:G,FALSE) -> 98530.343 | K48: =SUMIFS(Análise_Rescisões_Estrutura!I:I,Análise_Rescisões_Estrutura!E:E,Estrutura_Mínima_BEP!E48,Análise_Rescisões_Estrutura!H:H,FALSE) -> 69499.807
...

Sheet Mapa_Endividamento
B4: DÍVIDA | C4: GRUPO | D4: CREDOR | E4: GARANTIAS | F4: SALDO ATUAL | G4: PARCELAS | H4: VENCIMENTO | I4: Aprox. Juros [% a.m.] | J4: VALOR VENCIDO | L4: Termo da Dívida | M4: Valor Parcela | N4: Juros Mensais [R$/m]
B5: 1. Bancos | C5: GIROPRE | D5: Banco Itau | E5: SBLC (stand by) | F5: 4550000 | G5: =MAX(Empréstimos_e_Financiamento!J9-Empréstimos_e_Financiamento!K9,1) -> 1 | H5: MAI/2026 | I5: =N5/F5 -> 0.019050149 | M5: 0 | N5: 86678.18
C6: GIROPRE | D6: Banco Itau | F6: 2890000 | G6: =MAX(Empréstimos_e_Financiamento!J10-Empréstimos_e_Financiamento!K10,1) -> 1 | H6: MAI/2026 | I6: =N6/F6 -> 0.017820003 | M6: 0 | N6: 51499.81
C7: FINIMP | D7: Banco Brasil | F7: 766265.27 | G7: =MAX(Empréstimos_e_Financiamento!J21-Empréstimos_e_Financiamento!K21,1) -> 1 | H7: JUL/2025 | J7: 766265.27
C8: FINIMP | D8: Banco Brasil | F8: 383758.38 | G8: =MAX(Empréstimos_e_Financiamento!J20-Empréstimos_e_Financiamento!K20,1) -> 1 | H8: JUN/2025 | J8: 383758.38
C9: FINIMP | D9: Banco Brasil | F9: 317407.3 | G9: =MAX(Empréstimos_e_Financiamento!J23-Empréstimos_e_Financiamento!K23,1) -> 1 | H9: AGO/2025 | J9: 317407.3 | M9: 0
C10: FINIMP | D10: Banco Brasil | F10: 49372 | G10: =MAX(Empréstimos_e_Financiamento!J22-Empréstimos_e_Financiamento!K22,1) -> 1 | H10: AGO/2025 | J10: 49372
C11: SBLC (Stand by Letter of Credit) | F11: =SUM(F5:F10) -> 8956803 | J11: =SUM(J5:J10) -> 1516802.9
C12: GIRO | D12: Banco Brasil | E12: Aval Marcello | F12: =Empréstimos_e_Financiamento!G14 -> 1609756.2 | G12: =MAX(Empréstimos_e_Financiamento!J14-Empréstimos_e_Financiamento!K14,1) -> 33 | H12: MAR/2028 | J12: =Empréstimos_e_Financiamento!M14 -> 108195.19 | M12: =Empréstimos_e_Financiamento!H14 -> 48780.49
C13: FINAME | D13: Copel | F13: 1372792.7 | G13: =MAX(Empréstimos_e_Financiamento!J36-Empréstimos_e_Financiamento!K36,1) -> 84 | H13: JUL/2032 | J13: 0 | M13: 19266.64 | N13: 0
C14: NCE | D14: Santander | F14: =Empréstimos_e_Financiamento!G31 -> 742070.42 | G14: =MAX(Empréstimos_e_Financiamento!J31-Empréstimos_e_Financiamento!K31,1) -> 13 | H14: SET/2026 | J14: 0 | M14: =Empréstimos_e_Financiamento!H31 -> 57082.34
C15: GARANTIA | D15: Banco Itau | F15: 454364 | G15: =MAX(Empréstimos_e_Financiamento!J12-Empréstimos_e_Financiamento!K12,1) -> 1 | H15: JUN/2025 | I15: =N15/F15 -> 0.031499987 | M15: 0 | N15: 14312.46
C16: Aval Marcello | F16: =SUM(F12:F15) -> 4178983.3 | J16: =SUM(J12:J15) -> 108195.19
C17: =Empréstimos_e_Financiamento!C30 -> GIRO | D17: =Empréstimos_e_Financiamento!A30 -> BRADESCO | E17: Aval Flávio e Angelo | F17: =Empréstimos_e_Financiamento!G30 -> 949690.08 | G17: =Empréstimos_e_Financiamento!J30-Empréstimos_e_Financiamento!K30 -> 48 | H17: OUT/2029 | J17: =Empréstimos_e_Financiamento!M30 -> 0 | M17: =Empréstimos_e_Financiamento!H30 -> 19785.21 | N17: =Empréstimos_e_Financiamento!I30 -> 0
C18: =Empréstimos_e_Financiamento!C34 -> Renegociação de Divida | D18: =Empréstimos_e_Financiamento!A34 -> SANTANDER | F18: =Empréstimos_e_Financiamento!G34 -> 694099.92 | G18: =Empréstimos_e_Financiamento!J34 -> 24 | H18: SET/2027 | J18: =Empréstimos_e_Financiamento!M34 -> 0 | M18: =Empréstimos_e_Financiamento!H34 -> 28920.83 | N18: =Empréstimos_e_Financiamento!I34 -> 0
C19: =Empréstimos_e_Financiamento!C26 -> GARANTIA | D19: =Empréstimos_e_Financiamento!A26 -> BANCO BRASIL | F19: =Empréstimos_e_Financiamento!G26 -> 500000 | G19: 1 | H19: SET/2025 | I19: =N19/F19 -> 0.027 | J19: =Empréstimos_e_Financiamento!M26 -> 12514.82 | M19: =Empréstimos_e_Financiamento!H26 -> 0 | N19: =Empréstimos_e_Financiamento!I26 -> 13500
C20: =Empréstimos_e_Financiamento!C13 -> LIMITE C/C | D20: =Empréstimos_e_Financiamento!A13 -> BANCO ITAU | F20: =Empréstimos_e_Financiamento!G13 -> 350000 | G20: 1 | H20: JUN/2025 | I20: =N20/F20 -> 0.13895714 | J20: =Empréstimos_e_Financiamento!M13 -> 0 | M20: =Empréstimos_e_Financiamento!H13 -> 0 | N20: =Empréstimos_e_Financiamento!I13 -> 48635
C21: =Empréstimos_e_Financiamento!C15 -> GIRO | D21: =Empréstimos_e_Financiamento!A15 -> BANCO BRASIL | F21: =Empréstimos_e_Financiamento!G15 -> 347728.34 | G21: =Empréstimos_e_Financiamento!J15-Empréstimos_e_Financiamento!K15 -> 5 | H21: NOV/2025 | J21: =Empréstimos_e_Financiamento!M15 -> 175935.81 | M21: =Empréstimos_e_Financiamento!H15 -> 86868.12 | N21: =Empréstimos_e_Financiamento!I15 -> 0
C22: =Empréstimos_e_Financiamento!C24 -> Liquidação Finimp 409 | D22: =Empréstimos_e_Financiamento!A24 -> BANCO BRASIL | F22: =Empréstimos_e_Financiamento!G24 -> 278661.03 | G22: =Empréstimos_e_Financiamento!J24-Empréstimos_e_Financiamento!K24 -> 36 | H22: 22/07/2028 | J22: =Empréstimos_e_Financiamento!M24 -> 25456.82 | M22: =Empréstimos_e_Financiamento!H24 -> 12728.41 | N22: =Empréstimos_e_Financiamento!I24 -> 0
C23: =Empréstimos_e_Financiamento!C25 -> Liquidação Finimp 1166 | D23: =Empréstimos_e_Financiamento!A25 -> BANCO BRASIL | F23: =Empréstimos_e_Financiamento!G25 -> 269362.97 | G23: =Empréstimos_e_Financiamento!J25-Empréstimos_e_Financiamento!K25 -> 33 | H23: 18/06/2028 | J23: =Empréstimos_e_Financiamento!M25 -> 0 | M23: =Empréstimos_e_Financiamento!H25 -> 14045.43 | N23: =Empréstimos_e_Financiamento!I25 -> 0
C24: =Empréstimos_e_Financiamento!C35 -> LIMITE C/C | D24: =Empréstimos_e_Financiamento!A35 -> CAIXA | F24: =Empréstimos_e_Financiamento!G35 -> 100000 | G24: 1 | H24: JUN/2025 | I24: =N24/F24 -> 0.1379984 | J24: =Empréstimos_e_Financiamento!M35 -> 0 | M24: =Empréstimos_e_Financiamento!H35 -> 0 | N24: =Empréstimos_e_Financiamento!I35 -> 13799.84
C25: =Empréstimos_e_Financiamento!C27 -> LIMITE C/C | D25: =Empréstimos_e_Financiamento!A27 -> BANCO BRASIL | F25: =Empréstimos_e_Financiamento!G27 -> 24000 | G25: 1 | H25: JUN/2025 | J25: =Empréstimos_e_Financiamento!M27 -> 0 | M25: =Empréstimos_e_Financiamento!H27 -> 0 | N25: =Empréstimos_e_Financiamento!I27 -> 3768
C26: Aval Flávio/Angelo | F26: =SUM(F17:F25) -> 3513542.3 | J26: =SUM(J17:J25) -> 213907.45
C27: CDC | D27: Banco Itau | E27: Garantia Real - Carro Jeep | F27: =Empréstimos_e_Financiamento!G11 -> 40061.98 | G27: =MAX(Empréstimos_e_Financiamento!J11-Empréstimos_e_Financiamento!K11,1) -> 14 | H27: SET/2026 | M27: 4323.01 | N27: 0
C28: FINAME | D28: Banco Itau | E28: Garantia Real - Máquina Romi | F28: =Empréstimos_e_Financiamento!G8 -> 0 | G28: =MAX(Empréstimos_e_Financiamento!J8-Empréstimos_e_Financiamento!K8,1) -> 1 | H28: SET/2025 | J28: 14275.81 | M28: 14275.81 | N28: 0
C29: Garantia Real | F29: =SUM(F27:F28) -> 40061.98 | J29: =SUM(J27:J28) -> 14275.81
C30: ACC | D30: Banco Brasil | E30: Remessa exportação | F30: 1141740 | G30: =MAX(Empréstimos_e_Financiamento!J17-Empréstimos_e_Financiamento!K17,1) -> 1 | H30: DEZ/2025 | M30: 0 | N30: 0
C31: ACC | D31: Banco Brasil | F31: 719296.2 | G31: =MAX(Empréstimos_e_Financiamento!J16-Empréstimos_e_Financiamento!K16,1) -> 1 | H31: NOV/2025 | M31: 0 | N31: 0
C32: Remessa exportação | F32: =SUM(F30:F31) -> 1861036.2 | J32: =SUM(J30:J31) -> 0
C33: TOTAL | F33: =F32+F29+F26+F16+F11 -> 18550427 | J33: =J32+J29+J26+J16+J11 -> 1853181.4
B34: 2. Fornecedores | C34: A | F34: =SUMIFS(Aging_fornecedores!$D:$D,Aging_fornecedores!$G:$G,C34) -> 1529703.1 | J34: =SUMIFS(Aging_fornecedores!$P:$P,Aging_fornecedores!$G:$G,Mapa_Endividamento!C34) -> 1474383.7
C35: B | F35: =SUMIFS(Aging_fornecedores!$D:$D,Aging_fornecedores!$G:$G,C35) -> 938347.95 | J35: =SUMIFS(Aging_fornecedores!$P:$P,Aging_fornecedores!$G:$G,Mapa_Endividamento!C35) -> 907957.2
C36: C | F36: =SUMIFS(Aging_fornecedores!$D:$D,Aging_fornecedores!$G:$G,C36) -> 2174141.9 | J36: =SUMIFS(Aging_fornecedores!$P:$P,Aging_fornecedores!$G:$G,Mapa_Endividamento!C36) -> 2114034.8
C37: TOTAL | F37: =SUM(F34:F36) -> 4642192.9 | J37: =SUM(J34:J36) -> 4496375.8
B38: 3. Tributária | C38: ICMS | D38: Estado | F38: =SUMIFS('Dividas tributárias'!$I$8:$I$21,'Dividas tributárias'!$A$8:$A$21,Mapa_Endividamento!C38) -> 407232.2 | H38: JUN/2025 | J38: =F38 -> 407232.2
C39: INSS | D39: Federação | F39: =SUMIFS('Dividas tributárias'!$I$8:$I$21,'Dividas tributárias'!$A$8:$A$21,Mapa_Endividamento!C39) -> 638297.99 | H39: AGO/2025 | J39: =F39 -> 638297.99
C40: PIS | D40: Federação | F40: =SUMIFS('Dividas tributárias'!$I$8:$I$21,'Dividas tributárias'!$A$8:$A$21,Mapa_Endividamento!C40) -> 17866.02 | H40: JUL/2025 | J40: =F40 -> 17866.02
C41: COFINS | D41: Federação | F41: =SUMIFS('Dividas tributárias'!$I$8:$I$21,'Dividas tributárias'!$A$8:$A$21,Mapa_Endividamento!C41) -> 79862.84 | H41: JUL/2025 | J41: =F41 -> 79862.84
C42: IRRF | D42: Federação | F42: =SUMIFS('Dividas tributárias'!$I$8:$I$21,'Dividas tributárias'!$A$8:$A$21,Mapa_Endividamento!C42) -> 92074.93 | H42: AGO/2025 | J42: =F42 -> 92074.93
C43: IPTU | D43: Município | F43: =SUMIFS('Dividas tributárias'!$I$8:$I$21,'Dividas tributárias'!$A$8:$A$21,Mapa_Endividamento!C43) -> 152318.05 | H43: AGO/2025 | J43: =F43 -> 152318.05
...

Sheet Empréstimos_e_Financiamento
A1: Data de atualização: | C1: 29/08
A2: Ref. Documento: | C2: Empréstimos_e_Financiamento | N2: Conseguir credores pequenos
A4: MACLÍNEA - MÁQUINAS E EQUIPAMENTOS LTDA
A5: FINANCIAMENTOS E EMPRÉSTIMOS
I6: =H8*2 -> 0
A7: BANCO | B7: CONTRATO | C7: MODALIDADE | D7: GARANTIA | E7: FINALIDADE | F7: VCTO. | G7: SALDO | H7: Valor Parcela | I7: Juros Mensais | J7: Parcelas Totais | K7: Parcelas Quitadas | L7: Parcelas Vencidas | M7: Valores vencidos R$ | N7: Observações | O7: Parcelas Restantes | P7: Parcelas Restantes * Valor Parcela | T7: CONCATENADO | U7: VCTO.
A8: BANCO ITAU | B8: 400613744 | C8: FINAME | D8: próprio bem | E8: IMOBILIZADO | F8: SET/2025 | G8: 0 | H8: 0 | I8: 0 | J8: 60 | K8: 60 | L8: 0 | N8: Finame da Máquina Romi | O8: 1 | P8: 14275.81 | T8: =_xlfn.CONCAT(C8,"?",A8,"?",G8) -> FINAME?BANCO ITAU?0 | U8: SET/2025
A9: BANCO ITAU | B9: 769815952 | C9: GIROPRE | D9: SBLC (stand by) | E9: CAPITAL GIRO | F9: MAI/2026 | G9: 4550000 | H9: 0 | I9: 86678.18 | O9: 1 | P9: 0 | T9: =_xlfn.CONCAT(C9,"?",A9,"?",G9) -> GIROPRE?BANCO ITAU?4550000 | U9: MAI/2026
A10: BANCO ITAU | B10: 301162475 | C10: GIROPRE | D10: SBLC (stand by) | E10: CAPITAL GIRO | F10: MAI/2026 | G10: 2890000 | H10: 0 | I10: 51499.81 | O10: 1 | P10: 0 | T10: =_xlfn.CONCAT(C10,"?",A10,"?",G10) -> GIROPRE?BANCO ITAU?2890000 | U10: MAI/2026
A11: BANCO ITAU | B11: 17818842 | C11: CDC | D11: próprio bem | E11: IMOBILIZADO | F11: SET/2026 | G11: 40061.98 | H11: 4323.01 | I11: 0 | J11: 48 | K11: 34 | L11: 0 | N11: CDC do carro Jeep | O11: 14 | P11: 60522.14 | T11: =_xlfn.CONCAT(C11,"?",A11,"?",G11) -> CDC?BANCO ITAU?40061,98 | U11: SET/2026
A12: BANCO ITAU | B12: - | C12: GARANTIA | D12: aval Marcello | E12: CAPITAL GIRO | F12: JUN/2025 | G12: 454364 | H12: 0 | I12: 14312.46 | O12: 1 | P12: 0 | T12: =_xlfn.CONCAT(C12,"?",A12,"?",G12) -> GARANTIA?BANCO ITAU?454364 | U12: JUN/2025
A13: BANCO ITAU | B13: - | C13: LIMITE C/C | D13: aval Flávio | E13: CAPITAL GIRO | F13: JUN/2025 | G13: 350000 | H13: 0 | I13: 48635 | O13: 1 | P13: 0 | T13: =_xlfn.CONCAT(C13,"?",A13,"?",G13) -> LIMITE C/C?BANCO ITAU?350000 | U13: JUN/2025
A14: BANCO BRASIL | B14: 162218235 | C14: GIRO | D14: aval Marcello/Flavio | E14: CAPITAL GIRO | F14: MAR/2028 | G14: 1609756.2 | H14: 48780.49 | J14: 41 | K14: 8 | L14: 2 | M14: 108195.19 | N14: Valor apontado no Serasa | O14: 33 | P14: 1609756.2 | Q14: Valor das Parcelas * Parcelas Remanescentes muito próximo do saldo atual + Valor vencido acima do valor parcela | T14: =_xlfn.CONCAT(C14,"?",A14,"?",G14) -> GIRO ?BANCO BRASIL?1609756,17 | U14: MAR/2028
A15: BANCO BRASIL | B15: 162218545 | C15: GIRO | D15: aval Flávio/Angelo | E15: CAPITAL GIRO | F15: NOV/2025 | G15: 347728.34 | H15: 86868.12 | J15: 12 | K15: 7 | L15: 2 | M15: 175935.81 | N15: Valor apontado no Serasa | O15: 5 | P15: 434340.6 | Q15: Valor vencido acima do valor parcela | T15: =_xlfn.CONCAT(C15,"?",A15,"?",G15) -> GIRO ?BANCO BRASIL?347728,34 | U15: NOV/2025
A16: BANCO BRASIL | B16: 382982722 | C16: ACC | D16: remessa exportação | E16: CAPITAL GIRO | F16: NOV/2025 | G16: 719296.2 | H16: 0 | I16: 0 | N16: Não tem pagamento mensal, foi prorrogado para nov/2025 | O16: 1 | P16: 0 | T16: =_xlfn.CONCAT(C16,"?",A16,"?",G16) -> ACC?BANCO BRASIL?719296,2 | U16: NOV/2025
A17: BANCO BRASIL | B17: 419812219 | C17: ACC | D17: remessa exportação | E17: CAPITAL GIRO | F17: DEZ/2025 | G17: 1141740 | H17: 0 | I17: 0 | N17: Não tem pagamento mensal, foi prorrogado para dez/2025 | O17: 1 | P17: 0 | T17: =_xlfn.CONCAT(C17,"?",A17,"?",G17) -> ACC?BANCO BRASIL?1141740 | U17: DEZ/2025
A18: BANCO BRASIL | B18: 1166 | C18: FINIMP | D18: SBLC (stand by) | E18: CAPITAL GIRO | F18: ABR/2025 | H18: 0 | N18: Liquidado com empréstimo em 33 vezes | O18: 1 | P18: 0 | T18: =_xlfn.CONCAT(C18,"?",A18,"?",G18) -> FINIMP?BANCO BRASIL? | U18: ABR/2025
A19: BANCO BRASIL | B19: 409 | C19: FINIMP | D19: SBLC (stand by) | E19: CAPITAL GIRO | F19: MAI/2025 | H19: 0 | N19: Liquidado com empréstimo em 36 vezes | O19: 1 | P19: 0 | T19: =_xlfn.CONCAT(C19,"?",A19,"?",G19) -> FINIMP?BANCO BRASIL? | U19: MAI/2025
A20: BANCO BRASIL | B20: 98 | C20: FINIMP | D20: SBLC (stand by) | E20: CAPITAL GIRO | F20: JUN/2025 | G20: 383758.38 | M20: 383758.38 | N20: Vencido não foi possível a renovação, necessário pagamento de 30% banco ainda não exigiu | O20: 1 | P20: 0 | T20: =_xlfn.CONCAT(C20,"?",A20,"?",G20) -> FINIMP?BANCO BRASIL?383758,38 | U20: JUN/2025
A21: BANCO BRASIL | B21: 154 | C21: FINIMP | D21: SBLC (stand by) | E21: CAPITAL GIRO | F21: JUL/2025 | G21: 766265.27 | M21: 766265.27 | N21: Vencido não foi possível a renovação, necessário pagamento de 30% banco ainda não exigiu | O21: 1 | P21: 0 | T21: =_xlfn.CONCAT(C21,"?",A21,"?",G21) -> FINIMP?BANCO BRASIL?766265,27 | U21: JUL/2025
A22: BANCO BRASIL | B22: 721 | C22: FINIMP | D22: SBLC (stand by) | E22: CAPITAL GIRO | F22: AGO/2025 | G22: 49372 | M22: 49372 | N22: Vencido não foi possível a renovação, necessário pagamento de 30% banco ainda não exigiu | O22: 1 | P22: 0 | T22: =_xlfn.CONCAT(C22,"?",A22,"?",G22) -> FINIMP?BANCO BRASIL?49372 | U22: AGO/2025
A23: BANCO BRASIL | B23: 1910 | C23: FINIMP | D23: SBLC (stand by) | E23: CAPITAL GIRO | F23: AGO/2025 | G23: 317407.3 | H23: 0 | M23: 317407.3 | N23: Vencido não foi possível a renovação, necessário pagamento de 30% banco ainda não exigiu | O23: 1 | P23: 0 | T23: =_xlfn.CONCAT(C23,"?",A23,"?",G23) -> FINIMP?BANCO BRASIL?317407,3 | U23: AGO/2025
A24: BANCO BRASIL | B24: 162.218.974 | C24: Liquidação Finimp 409 | D24: Flávio/Angelo | E24: CAPITAL GIRO | F24: 22/07/2028 | G24: 278661.03 | H24: 12728.41 | J24: 36 | K24: 0 | L24: 2 | M24: =12728.41*2 -> 25456.82 | N24: Primeira parcela em 22/08/2025 | O24: 36 | P24: 458222.76 | T24: =_xlfn.CONCAT(C24,"?",A24,"?",G24) -> Liquidação Finimp 409?BANCO BRASIL?278661,03 | U24: 22/07/2028
A25: BANCO BRASIL | B25: 162.218.949 | C25: Liquidação Finimp 1166 | D25: Flávio/Angelo | E25: CAPITAL GIRO | F25: 18/06/2028 | G25: 269362.97 | H25: 14045.43 | J25: 33 | K25: 0 | L25: 0 | N25: Primeira parcela em 18/10/2025 | O25: 33 | P25: 463499.19 | T25: =_xlfn.CONCAT(C25,"?",A25,"?",G25) -> Liquidação Finimp 1166?BANCO BRASIL?269362,97 | U25: 18/06/2028
A26: BANCO BRASIL | B26: - | C26: GARANTIA | D26: Flávio/Angelo | E26: CAPITAL GIRO | F26: SET/2025 | G26: 500000 | I26: 13500 | M26: 12514.82 | N26: Juros de julho não foi pago valor apontado no Serasa | O26: 1 | P26: 0 | T26: =_xlfn.CONCAT(C26,"?",A26,"?",G26) -> GARANTIA?BANCO BRASIL?500000 | U26: SET/2025
A27: BANCO BRASIL | B27: - | C27: LIMITE C/C | D27: Flávio/Angelo | E27: CAPITAL GIRO | F27: JUN/2025 | G27: 24000 | I27: 3768 | O27: 1 | P27: 0 | T27: =_xlfn.CONCAT(C27,"?",A27,"?",G27) -> LIMITE C/C?BANCO BRASIL?24000 | U27: JUN/2025
A28: BRADESCO | B28: 16631120 | C28: GIRO | D28: aval Flávio | E28: CAPITAL GIRO | F28: JUN/2026 | N28: Renegociado 216.666 + 47753,88 = 264.420,88 | O28: 0 | P28: 0 | Q28: Valor vencido acima do valor parcela | T28: =_xlfn.CONCAT(C28,"?",A28,"?",G28) -> GIRO?BRADESCO? | U28: JUN/2026
A29: BRADESCO | B29: 16808214 | C29: GIRO | D29: aval Flávio | E29: CAPITAL GIRO | F29: OUT/2026 | N29: Renegociado 233.750 + 39961,44 = 273.711,44 | O29: 0 | P29: 0 | Q29: Valor vencido acima do valor parcela | T29: =_xlfn.CONCAT(C29,"?",A29,"?",G29) -> GIRO?BRADESCO? | U29: OUT/2026
A30: BRADESCO | B30: 17283962 | C30: GIRO | D30: aval Flávio e Angelo | E30: CAPITAL GIRO | F30: OUT/2029 | G30: 949690.08 | H30: 19785.21 | J30: 48 | K30: 0 | L30: 0 | N30: Ref renegociação Carencia 3 meses - 1 parcela 21/11/2025, ultima 10/10/2025 | O30: 48 | P30: 949690.08 | T30: =_xlfn.CONCAT(C30,"?",A30,"?",G30) -> GIRO?BRADESCO?949690,08 | U30: OUT/2029
A31: SANTANDER | B31: 37180 | C31: NCE | D31: aval Marcello | E31: CAPITAL GIRO | F31: SET/2026 | G31: 742070.42 | H31: 57082.34 | J31: 36 | K31: 23 | L31: 0 | O31: 13 | P31: 742070.42 | Q31: Valor das Parcelas * Parcelas Remanescentes abaixo do saldo atual | T31: =_xlfn.CONCAT(C31,"?",A31,"?",G31) -> NCE?SANTANDER?742070,42 | U31: SET/2026
A32: SANTANDER | B32: - | C32: GARANTIA | D32: aval Flávio | E32: CAPITAL GIRO | F32: JUN/2025 | N32: Renegociado em 28/08/2025 - 24 parcelas x 28.920,83 - 1 parc 22/10/25 ultima 22/09/2027 | O32: 24 | P32: 0 | Q32: Não tem informação do juros | T32: =_xlfn.CONCAT(C32,"?",A32,"?",G32) -> GARANTIA?SANTANDER? | U32: JUN/2025
A33: SANTANDER | B33: - | C33: LIMITE C/C | D33: aval Flávio | E33: CAPITAL GIRO | F33: JUN/2025 | H33: 0 | N33: Renegociado em 28/08/2025 - 24 parcelas x 28.920,83 - 1 parc 22/10/25 ultima 22/09/2027 | O33: 1 | P33: 0 | T33: =_xlfn.CONCAT(C33,"?",A33,"?",G33) -> LIMITE C/C?SANTANDER? | U33: JUN/2025
A34: SANTANDER | B34: 00332190300000047430 | C34: Renegociação de Divida | D34: aval Flávio e Angelo | E34: CAPITAL GIRO | F34: SET/2027 | G34: 694099.92 | H34: 28920.83 | J34: 24 | K34: 0 | L34: 0 | N34: Ref renegociação do conta garantida de 400 mil e o limite de cheque especial 90 mil | O34: 1 | T34: =_xlfn.CONCAT(C34,"?",A34,"?",G34) -> Renegociação de Divida?SANTANDER?694099,92 | U34: SET/2027
A35: CAIXA | B35: - | C35: LIMITE C/C | D35: aval Flávio | E35: CAPITAL GIRO | F35: JUN/2025 | G35: 100000 | H35: 0 | I35: 13799.84 | O35: 1 | P35: 0 | T35: =_xlfn.CONCAT(C35,"?",A35,"?",G35) -> LIMITE C/C?CAIXA?100000 | U35: JUN/2025
A36: COPEL | B36: 4600022060 | C36: FINAME | D36: aval Marcello | E36: IMOBILIZADO | F36: JUL/2032 | G36: 1372792.7 | H36: 19266.64 | I36: 0 | J36: 89 | K36: 5 | L36: 0 | M36: 0 | N36: Financiamento sistema de geração de energia solar - placas solares | O36: 84 | P36: 1618397.8 | T36: =_xlfn.CONCAT(C36,"?",A36,"?",G36) -> FINAME?COPEL?1372792,67 | U36: JUL/2032
F37: TOTAL | G37: =SUM(G8:G36) -> 18550427 | H37: =SUM(H8:H36) -> 291800.48 | I37: =SUM(I8:I36) -> 232193.29 | M37: =SUM(M8:M36) -> 1838905.6 | T37: =_xlfn.CONCAT(C37,"?",A37,"?",G37) -> ??18550426,73 | U37: TOTAL
F38: TOTAL MÊS | I38: =I37+H37 -> 523993.77 | U38: TOTAL MÊS
F40: Dívida que vai ser impactada por juros ou multa | G40: =G12+G13+SUM(G20:G23)+G26+G27+G35 -> 2945167 | U40: Dívida que vai ser impactada por juros ou multa

Sheet Premissas_Receita
D1: Data de atualização: | G1: 45901
D2: Ref. Documento: | G2: 202508_Maclinea_Reorganization_Analysis_Provisório_rev03
M3: =Premissas_COGS!I3 -> 0.009
C4: Peças e Service | I4: Receita Bruta (Mensal) | J4: Impostos | K4: Receita Líquida (Mensal) | M4: Comissão | O4: Material (unitário) | P4: MOD | Q4: Instalação | R4: Custo Total | T4: MdC | U4: % | V4: 1a Margem
A5: Peças | D5: Comprados | I5: =VLOOKUP(D5,Premissas_COGS!C:E,3,0) -> 400000 | J5: =VLOOKUP(D5,Premissas_COGS!C:F,4,0) -> 0.2354 | K5: =I5*(1-J5) -> 305840 | M5: =$M$3*K5 -> 2752.56 | O5: =VLOOKUP(D5,Premissas_COGS!C:L,9,0) -> 226680 | R5: =SUM(O5:Q5) -> 226680 | T5: =K5-M5-R5 -> 76407.44 | U5: =T5/(K5-M5) -> 0.25209702 | V5: =T5+P5+Q5 -> 76407.44 | W5: =V5/(K5-M5) -> 0.25209702
A6: Peças | D6: Fabricados | I6: =VLOOKUP(D6,Premissas_COGS!C:E,3,0) -> 300000 | J6: =VLOOKUP(D6,Premissas_COGS!C:F,4,0) -> 0.2354 | K6: =I6*(1-J6) -> 229380 | M6: =$M$3*K6 -> 2064.42 | O6: =VLOOKUP(D6,Premissas_COGS!C:L,9,0) -> 102006 | P6: =VLOOKUP(D6,Premissas_COGS!C:L,10,0) -> 34002 | R6: =SUM(O6:Q6) -> 136008 | T6: =K6-M6-R6 -> 91307.58 | U6: =T6/(K6-M6) -> 0.40167761 | V6: =T6+P6+Q6 -> 125309.58 | W6: =V6/(K6-M6) -> 0.55125821
A7: Service | D7: Service | I7: =VLOOKUP(D7,Premissas_COGS!C:E,3,0) -> 150000 | J7: =VLOOKUP(D7,Premissas_COGS!C:F,4,0) -> 0.1425 | K7: =I7*(1-J7) -> 128625 | M7: =$M$3*K7 -> 1157.625 | P7: =VLOOKUP(D7,Premissas_COGS!C:L,10,0) -> 82729 | R7: =SUM(O7:Q7) -> 82729 | T7: =K7-M7-R7 -> 44738.375 | U7: =T7/(K7-M7) -> 0.35097903 | V7: =T7+P7+Q7 -> 127467.38 | W7: =V7/(K7-M7) -> 1
M9: =Premissas_COGS!I9 -> 0.05 | P9: 0.25
C10: Máquinas Pequenas | F10: Qtde (ano) | G10: Qtde (mês) | H10: Preço | I10: Receita Bruta (Mensal) | J10: Impostos | K10: Receita Líquida (Mensal) | M10: Comissão | O10: Material (unitário) | P10: MOD | Q10: Instalação | R10: Custo Total | T10: MdC | U10: % | V10: 1a Margem
A11: Máquinas Pequenas | D11: Impact | F11: 6 | G11: =F11/12 -> 0.5 | H11: 230000 | I11: =H11*G11 -> 115000 | J11: =VLOOKUP(D11,Premissas_COGS!C:F,4,0) -> 0.1724 | K11: =I11-(J11*I11) -> 95174 | M11: =$M$9*K11 -> 4758.7 | O11: =VLOOKUP(D11,Premissas_COGS!C:L,9,0)*G11 -> 60881.925 | P11: =VLOOKUP(D11,Premissas_COGS!C:L,10,0)*G11 -> 21250 | Q11: =VLOOKUP(D11,Premissas_COGS!C:M,11,0)*G11 -> 2868.075 | R11: =SUM(O11:Q11) -> 85000 | T11: =K11-R11-M11 -> 5415.3 | U11: =T11/(K11-M11) -> 0.059893624 | V11: =T11+P11+Q11 -> 29533.375 | W11: =V11/(K11-M11) -> 0.32664134
A12: Máquinas Pequenas | D12: Fast | F12: 2 | G12: =F12/12 -> 0.16666667 | H12: 130000 | I12: =H12*G12 -> 21666.667 | J12: =VLOOKUP(D12,Premissas_COGS!C:F,4,0) -> 0.1724 | K12: =I12-(J12*I12) -> 17931.333 | M12: =$M$9*K12 -> 896.56667 | O12: =VLOOKUP(D12,Premissas_COGS!C:L,9,0)*G12 -> 10840.275 | P12: =VLOOKUP(D12,Premissas_COGS!C:L,10,0)*G12 -> 3750 | Q12: =VLOOKUP(D12,Premissas_COGS!C:M,11,0)*G12 -> 409.725 | R12: =SUM(O12:Q12) -> 15000 | T12: =K12-R12-M12 -> 2034.7667 | U12: =T12/(K12-M12) -> 0.11944787 | V12: =T12+P12+Q12 -> 6194.4917 | W12: =V12/(K12-M12) -> 0.36363819
A13: Máquinas Pequenas | D13: Fast PN | F13: 4 | G13: =F13/12 -> 0.33333333 | H13: 250000 | I13: =H13*G13 -> 83333.333 | J13: =VLOOKUP(D13,Premissas_COGS!C:F,4,0) -> 0.1724 | K13: =I13-(J13*I13) -> 68966.667 | M13: =$M$9*K13 -> 3448.3333 | O13: =VLOOKUP(D13,Premissas_COGS!C:L,9,0)*G13 -> 44064.8 | P13: =VLOOKUP(D13,Premissas_COGS!C:L,10,0)*G13 -> 15416.667 | Q13: =VLOOKUP(D13,Premissas_COGS!C:M,11,0)*G13 -> 2185.2 | R13: =SUM(O13:Q13) -> 61666.667 | T13: =K13-R13-M13 -> 3851.6667 | U13: =T13/(K13-M13) -> 0.058787617 | V13: =T13+P13+Q13 -> 21453.533 | W13: =V13/(K13-M13) -> 0.32744321
A14: Máquinas Pequenas | D14: Smart | F14: 5 | G14: =F14/12 -> 0.41666667 | H14: 350000 | I14: =H14*G14 -> 145833.33 | J14: =VLOOKUP(D14,Premissas_COGS!C:F,4,0) -> 0.1724 | K14: =I14-(J14*I14) -> 120691.67 | M14: =$M$9*K14 -> 6034.5833 | O14: =VLOOKUP(D14,Premissas_COGS!C:L,9,0)*G14 -> 56131.062 | P14: =VLOOKUP(D14,Premissas_COGS!C:L,10,0)*G14 -> 19393.229 | Q14: =VLOOKUP(D14,Premissas_COGS!C:M,11,0)*G14 -> 2048.625 | R14: =SUM(O14:Q14) -> 77572.917 | T14: =K14-R14-M14 -> 37084.167 | U14: =T14/(K14-M14) -> 0.32343546 | V14: =T14+P14+Q14 -> 58526.021 | W14: =V14/(K14-M14) -> 0.51044401
M16: =Premissas_COGS!I16 -> 0.05
C17: Máquinas Grandes | F17: Qtde (ano) | G17: Qtde (mês) | H17: Preço | I17: Receita Bruta (Mensal) | J17: Impostos | K17: Receita Líquida (Mensal) | M17: Comissão | O17: Material | P17: MOD | Q17: Instalação | R17: Custo Total | T17: MdC | U17: % | V17: 1a Margem
A18: Máquinas Grandes | D18: Gemini | F18: 3 | G18: =F18/12 -> 0.25 | H18: =VLOOKUP(D18,Premissas_COGS!C:E,3,0) -> 1050000 | I18: =H18*G18 -> 262500 | J18: =VLOOKUP(D18,Premissas_COGS!C:F,4,0) -> 0.1724 | K18: =I18-(J18*I18) -> 217245 | M18: =$M$16*K18 -> 10862.25 | O18: =VLOOKUP(D18,Premissas_COGS!C:L,9,0)*G18 -> 102052.2 | P18: =VLOOKUP(D18,Premissas_COGS!C:L,10,0)*G18 -> 34427.125 | Q18: =VLOOKUP(D18,Premissas_COGS!C:M,11,0)*G18 -> 1229.175 | R18: =SUM(O18:Q18) -> 137708.5 | T18: =K18-R18-M18 -> 68674.25 | U18: =T18/(K18-M18) -> 0.33275189 | V18: =T18+P18+Q18 -> 104330.55 | W18: =V18/(K18-M18) -> 0.50551972
A19: Máquinas Grandes | D19: Europa 2G | F19: 3 | G19: =F19/12 -> 0.25 | H19: =VLOOKUP(D19,Premissas_COGS!C:E,3,0) -> 420000 | I19: =H19*G19 -> 105000 | J19: =VLOOKUP(D19,Premissas_COGS!C:F,4,0) -> 0.1724 | K19: =I19-(J19*I19) -> 86898 | M19: =$M$16*K19 -> 4344.9 | O19: =VLOOKUP(D19,Premissas_COGS!C:L,9,0)*G19 -> 45670.35 | P19: =VLOOKUP(D19,Premissas_COGS!C:L,10,0)*G19 -> 15769.75 | Q19: =VLOOKUP(D19,Premissas_COGS!C:M,11,0)*G19 -> 1638.9 | R19: =SUM(O19:Q19) -> 63079 | T19: =K19-R19-M19 -> 19474.1 | U19: =T19/(K19-M19) -> 0.23589786 | V19: =T19+P19+Q19 -> 36882.75 | W19: =V19/(K19-M19) -> 0.44677608
A20: Máquinas Grandes | D20: Europa 3G | F20: 3 | G20: =F20/12 -> 0.25 | H20: =VLOOKUP(D20,Premissas_COGS!C:E,3,0) -> 500000 | I20: =H20*G20 -> 125000 | J20: =VLOOKUP(D20,Premissas_COGS!C:F,4,0) -> 0.1724 | K20: =I20-(J20*I20) -> 103450 | M20: =$M$16*K20 -> 5172.5 | O20: =VLOOKUP(D20,Premissas_COGS!C:L,9,0)*G20 -> 54484.163 | P20: =VLOOKUP(D20,Premissas_COGS!C:L,10,0)*G20 -> 18707.688 | Q20: =VLOOKUP(D20,Premissas_COGS!C:M,11,0)*G20 -> 1638.9 | R20: =SUM(O20:Q20) -> 74830.75 | T20: =K20-R20-M20 -> 23446.75 | U20: =T20/(K20-M20) -> 0.23857699 | V20: =T20+P20+Q20 -> 43793.338 | W20: =V20/(K20-M20) -> 0.44560899
A21: Máquinas Grandes | C21: Linha de pintura
A22: Máquinas Grandes | D22: ERS 130 T | F22: 7 | G22: =F22/12 -> 0.58333333 | H22: =VLOOKUP(D22,Premissas_COGS!C:E,3,0) -> 140000 | I22: =H22*G22 -> 81666.667 | J22: =VLOOKUP(D22,Premissas_COGS!C:F,4,0) -> 0.1724 | K22: =I22-(J22*I22) -> 67587.333 | M22: =$M$16*K22 -> 3379.3667 | O22: =VLOOKUP(D22,Premissas_COGS!C:L,9,0)*G22 -> 33758.55 | P22: =VLOOKUP(D22,Premissas_COGS!C:L,10,0)*G22 -> 12208.875 | Q22: =VLOOKUP(D22,Premissas_COGS!C:M,11,0)*G22 -> 2868.075 | R22: =SUM(O22:Q22) -> 48835.5 | T22: =K22-R22-M22 -> 15372.467 | U22: =T22/(K22-M22) -> 0.23941681 | V22: =T22+P22+Q22 -> 30449.417 | W22: =V22/(K22-M22) -> 0.47423113
A23: Máquinas Grandes | D23: ERS 130 T2 | F23: 7 | G23: =F23/12 -> 0.58333333 | H23: =VLOOKUP(D23,Premissas_COGS!C:E,3,0) -> 242000 | I23: =H23*G23 -> 141166.67 | J23: =VLOOKUP(D23,Premissas_COGS!C:F,4,0) -> 0.1724 | K23: =I23-(J23*I23) -> 116829.53 | M23: =$M$16*K23 -> 5841.4767 | O23: =VLOOKUP(D23,Premissas_COGS!C:L,9,0)*G23 -> 59610.862 | P23: =VLOOKUP(D23,Premissas_COGS!C:L,10,0)*G23 -> 20826.312 | Q23: =VLOOKUP(D23,Premissas_COGS!C:M,11,0)*G23 -> 2868.075 | R23: =SUM(O23:Q23) -> 83305.25 | T23: =K23-R23-M23 -> 27682.807 | U23: =T23/(K23-M23) -> 0.24942149 | V23: =T23+P23+Q23 -> 51377.194 | W23: =V23/(K23-M23) -> 0.46290741
A24: Máquinas Grandes | D24: ALS 130 T | F24: 2 | G24: =F24/12 -> 0.16666667 | H24: =VLOOKUP(D24,Premissas_COGS!C:E,3,0) -> 220000 | I24: =H24*G24 -> 36666.667 | J24: =VLOOKUP(D24,Premissas_COGS!C:F,4,0) -> 0.1724 | K24: =I24-(J24*I24) -> 30345.333 | M24: =$M$16*K24 -> 1517.2667 | O24: =VLOOKUP(D24,Premissas_COGS!C:L,9,0)*G24 -> 15702.025 | P24: =VLOOKUP(D24,Premissas_COGS!C:L,10,0)*G24 -> 5370.5833 | Q24: =VLOOKUP(D24,Premissas_COGS!C:M,11,0)*G24 -> 409.725 | R24: =SUM(O24:Q24) -> 21482.333 | T24: =K24-R24-M24 -> 7345.7333 | U24: =T24/(K24-M24) -> 0.25481186 | V24: =T24+P24+Q24 -> 13126.042 | W24: =V24/(K24-M24) -> 0.45532161
A25: Máquinas Grandes | D25: ESP 130 | F25: 2 | G25: =F25/12 -> 0.16666667 | H25: =VLOOKUP(D25,Premissas_COGS!C:E,3,0) -> 220000 | I25: =H25*G25 -> 36666.667 | J25: =VLOOKUP(D25,Premissas_COGS!C:F,4,0) -> 0.1724 | K25: =I25-(J25*I25) -> 30345.333 | M25: =$M$16*K25 -> 1517.2667 | O25: =VLOOKUP(D25,Premissas_COGS!C:L,9,0)*G25 -> 15702.025 | P25: =VLOOKUP(D25,Premissas_COGS!C:L,10,0)*G25 -> 5370.5833 | Q25: =VLOOKUP(D25,Premissas_COGS!C:M,11,0)*G25 -> 409.725 | R25: =SUM(O25:Q25) -> 21482.333 | T25: =K25-R25-M25 -> 7345.7333 | U25: =T25/(K25-M25) -> 0.25481186 | V25: =T25+P25+Q25 -> 13126.042 | W25: =V25/(K25-M25) -> 0.45532161
A26: Máquinas Grandes | D26: TUV 2L | F26: 5 | G26: =F26/12 -> 0.41666667 | H26: =VLOOKUP(D26,Premissas_COGS!C:E,3,0) -> 113000 | I26: =H26*G26 -> 47083.333 | J26: =VLOOKUP(D26,Premissas_COGS!C:F,4,0) -> 0.1724 | K26: =I26-(J26*I26) -> 38966.167 | M26: =$M$16*K26 -> 1948.3083 | O26: =VLOOKUP(D26,Premissas_COGS!C:L,9,0)*G26 -> 19448.625 | P26: =VLOOKUP(D26,Premissas_COGS!C:L,10,0)*G26 -> 6938.125 | Q26: =VLOOKUP(D26,Premissas_COGS!C:M,11,0)*G26 -> 1365.75 | R26: =SUM(O26:Q26) -> 27752.5 | T26: =K26-R26-M26 -> 9265.3583 | U26: =T26/(K26-M26) -> 0.25029428 | V26: =T26+P26+Q26 -> 17569.233 | W26: =V26/(K26-M26) -> 0.47461507
A27: Máquinas Grandes | D27: TUV 3L | F27: 5 | G27: =F27/12 -> 0.41666667 | H27: =VLOOKUP(D27,Premissas_COGS!C:E,3,0) -> 127000 | I27: =H27*G27 -> 52916.667 | J27: =VLOOKUP(D27,Premissas_COGS!C:F,4,0) -> 0.1724 | K27: =I27-(J27*I27) -> 43793.833 | M27: =$M$16*K27 -> 2189.6917 | O27: =VLOOKUP(D27,Premissas_COGS!C:L,9,0)*G27 -> 21925.5 | P27: =VLOOKUP(D27,Premissas_COGS!C:L,10,0)*G27 -> 7763.75 | Q27: =VLOOKUP(D27,Premissas_COGS!C:M,11,0)*G27 -> 1365.75 | R27: =SUM(O27:Q27) -> 31055 | T27: =K27-R27-M27 -> 10549.142 | U27: =T27/(K27-M27) -> 0.25355989 | V27: =T27+P27+Q27 -> 19678.642 | W27: =V27/(K27-M27) -> 0.47299718
A28: Máquinas Grandes | D28: IMP 130 T | F28: 2 | G28: =F28/12 -> 0.16666667 | H28: =VLOOKUP(D28,Premissas_COGS!C:E,3,0) -> 252000 | I28: =H28*G28 -> 42000 | J28: =VLOOKUP(D28,Premissas_COGS!C:F,4,0) -> 0.1724 | K28: =I28-(J28*I28) -> 34759.2 | M28: =$M$16*K28 -> 1737.96 | O28: =VLOOKUP(D28,Premissas_COGS!C:L,9,0)*G28 -> 17255.55 | P28: =VLOOKUP(D28,Premissas_COGS!C:L,10,0)*G28 -> 6025 | Q28: =VLOOKUP(D28,Premissas_COGS!C:M,11,0)*G28 -> 819.45 | R28: =SUM(O28:Q28) -> 24100 | T28: =K28-R28-M28 -> 8921.24 | U28: =T28/(K28-M28) -> 0.27016672 | V28: =T28+P28+Q28 -> 15765.69 | W28: =V28/(K28-M28) -> 0.47744088
A29: Máquinas Grandes | D29: TRANSFER | F29: 6 | G29: =F29/12 -> 0.5 | H29: =VLOOKUP(D29,Premissas_COGS!C:E,3,0) -> 50000 | I29: =H29*G29 -> 25000 | J29: =VLOOKUP(D29,Premissas_COGS!C:F,4,0) -> 0.1724 | K29: =I29-(J29*I29) -> 20690 | M29: =$M$16*K29 -> 1034.5 | O29: =VLOOKUP(D29,Premissas_COGS!C:L,9,0)*G29 -> 10993.05 | P29: =VLOOKUP(D29,Premissas_COGS!C:L,10,0)*G29 -> 3937.5 | Q29: =VLOOKUP(D29,Premissas_COGS!C:M,11,0)*G29 -> 819.45 | R29: =SUM(O29:Q29) -> 15750 | T29: =K29-R29-M29 -> 3905.5 | U29: =T29/(K29-M29) -> 0.19869757 | V29: =T29+P29+Q29 -> 8662.45 | W29: =V29/(K29-M29) -> 0.4407138

Sheet Premissas_COGS
B1: Data de atualização: | E1: 45901
B2: Ref. Documento: | E2: Visita Agosto
I3: 0.009
B4: Peças e Service | E4: Receita Mensal | F4: Impostos | G4: Receita Líquida Mensal | I4: Comissão | K4: Material (A) | L4: MOD (B) | M4: Instalação (C) | N4: Custo total (A+B+C) | P4: MdC | Q4: (%) | R4: 1a Margem | S4: (%)
C5: Comprados | E5: 400000 | F5: 0.2354 | G5: =E5*(1-F5) -> 305840 | I5: =$I$3*G5 -> 2752.56 | K5: 226680 | N5: =SUM(K5:M5) -> 226680 | P5: =G5-I5-N5 -> 76407.44 | Q5: =P5/(G5-I5) -> 0.25209702 | R5: =P5+L5+M5 -> 76407.44 | S5: =R5/(G5-I5) -> 0.25209702
C6: Fabricados | E6: 300000 | F6: 0.2354 | G6: =E6*(1-F6) -> 229380 | I6: =$I$3*G6 -> 2064.42 | K6: 102006 | L6: 34002 | N6: =SUM(K6:M6) -> 136008 | P6: =G6-I6-N6 -> 91307.58 | Q6: =P6/(G6-I6) -> 0.40167761 | R6: =P6+L6+M6 -> 125309.58 | S6: =R6/(G6-I6) -> 0.55125821
C7: Service | E7: 150000 | F7: 0.1425 | G7: =E7*(1-F7) -> 128625 | I7: =$I$3*G7 -> 1157.625 | L7: 82729 | N7: =SUM(K7:M7) -> 82729 | P7: =G7-I7-N7 -> 44738.375 | Q7: =P7/(G7-I7) -> 0.35097903 | R7: =P7+L7+M7 -> 127467.38 | S7: =R7/(G7-I7) -> 1
I9: 0.05 | L9: 0.25
B10: Máquinas Pequenas | E10: Preço | F10: Impostos | G10: Preço líquido | I10: Comissão | K10: Material (A) | L10: MOD (B) | M10: Instalação (C) | N10: Custo total (A+B+C) | P10: MdC | Q10: (%) | R10: 1a Margem | S10: (%)
C11: Impact | E11: 230000 | F11: 0.1724 | G11: =E11*(1-F11) -> 190348 | I11: =G11*$I$9 -> 9517.4 | K11: =N11-M11-L11 -> 121763.85 | L11: =$L$9*N11 -> 42500 | M11: 5736.15 | N11: 170000 | P11: =G11-N11-I11 -> 10830.6 | Q11: =P11/(G11-I11) -> 0.059893624 | R11: =P11+L11+M11 -> 59066.75 | S11: =R11/(G11-I11) -> 0.32664134
C12: Fast | E12: 130000 | F12: 0.1724 | G12: =E12*(1-F12) -> 107588 | I12: =G12*$I$9 -> 5379.4 | K12: =N12-M12-L12 -> 65041.65 | L12: =$L$9*N12 -> 22500 | M12: 2458.35 | N12: 90000 | P12: =G12-N12-I12 -> 12208.6 | Q12: =P12/(G12-I12) -> 0.11944787 | R12: =P12+L12+M12 -> 37166.95 | S12: =R12/(G12-I12) -> 0.36363819
C13: Fast PN | E13: 250000 | F13: 0.1724 | G13: =E13*(1-F13) -> 206900 | I13: =G13*$I$9 -> 10345 | K13: =N13-M13-L13 -> 132194.4 | L13: =$L$9*N13 -> 46250 | M13: 6555.6 | N13: 185000 | P13: =G13-N13-I13 -> 11555 | Q13: =P13/(G13-I13) -> 0.058787617 | R13: =P13+L13+M13 -> 64360.6 | S13: =R13/(G13-I13) -> 0.32744321
C14: Smart | E14: 350000 | F14: 0.1724 | G14: =E14*(1-F14) -> 289660 | I14: =G14*$I$9 -> 14483 | K14: =N14-M14-L14 -> 134714.55 | L14: =$L$9*N14 -> 46543.75 | M14: 4916.7 | N14: 186175 | P14: =G14-N14-I14 -> 89002 | Q14: =P14/(G14-I14) -> 0.32343546 | R14: =P14+L14+M14 -> 140462.45 | S14: =R14/(G14-I14) -> 0.51044401
I16: 0.05 | L16: 0.25
B17: Máquinas Grandes | E17: Preço | F17: Impostos | G17: Preço líquido | I17: Comissão | K17: Material (A) | L17: MOD (B) | M17: Instalação (C) | N17: Custo total (A+B+C) | P17: MdC | Q17: (%) | R17: 1a Margem | S17: (%)
C18: Gemini | E18: 1050000 | F18: 0.1724 | G18: =E18*(1-F18) -> 868980 | I18: =$I$16*G18 -> 43449 | K18: 408208.8 | L18: 137708.5 | M18: 4916.7 | N18: 550834 | P18: =G18-N18-I18 -> 274697 | Q18: =P18/(G18-I18) -> 0.33275189 | R18: =P18+L18+M18 -> 417322.2 | S18: =R18/(G18-I18) -> 0.50551972
C19: Europa 2G | E19: 420000 | F19: 0.1724 | G19: =E19*(1-F19) -> 347592 | I19: =$I$16*G19 -> 17379.6 | K19: 182681.4 | L19: 63079 | M19: 6555.6 | N19: 252316 | P19: =G19-N19-I19 -> 77896.4 | Q19: =P19/(G19-I19) -> 0.23589786 | R19: =P19+L19+M19 -> 147531 | S19: =R19/(G19-I19) -> 0.44677608
C20: Europa 3G | E20: 500000 | F20: 0.1724 | G20: =E20*(1-F20) -> 413800 | I20: =$I$16*G20 -> 20690 | K20: 217936.65 | L20: 74830.75 | M20: 6555.6 | N20: 299323 | P20: =G20-N20-I20 -> 93787 | Q20: =P20/(G20-I20) -> 0.23857699 | R20: =P20+L20+M20 -> 175173.35 | S20: =R20/(G20-I20) -> 0.44560899
B21: Linha de pintura
C22: ERS 130 T | E22: 140000 | F22: 0.1724 | G22: =E22*(1-F22) -> 115864 | I22: =$I$16*G22 -> 5793.2 | K22: 57871.8 | L22: 20929.5 | M22: 4916.7 | N22: 83718 | P22: =G22-N22-I22 -> 26352.8 | Q22: =P22/(G22-I22) -> 0.23941681 | R22: =P22+L22+M22 -> 52199 | S22: =R22/(G22-I22) -> 0.47423113
C23: ERS 130 T2 | E23: 242000 | F23: 0.1724 | G23: =E23*(1-F23) -> 200279.2 | I23: =$I$16*G23 -> 10013.96 | K23: 102190.05 | L23: 35702.25 | M23: 4916.7 | N23: 142809 | P23: =G23-N23-I23 -> 47456.24 | Q23: =P23/(G23-I23) -> 0.24942149 | R23: =P23+L23+M23 -> 88075.19 | S23: =R23/(G23-I23) -> 0.46290741
C24: ALS 130 T | E24: 220000 | F24: 0.1724 | G24: =E24*(1-F24) -> 182072 | I24: =$I$16*G24 -> 9103.6 | K24: 94212.15 | L24: 32223.5 | M24: 2458.35 | N24: 128894 | P24: =G24-N24-I24 -> 44074.4 | Q24: =P24/(G24-I24) -> 0.25481186 | R24: =P24+L24+M24 -> 78756.25 | S24: =R24/(G24-I24) -> 0.45532161
C25: ESP 130 | E25: 220000 | F25: 0.1724 | G25: =E25*(1-F25) -> 182072 | I25: =$I$16*G25 -> 9103.6 | K25: 94212.15 | L25: 32223.5 | M25: 2458.35 | N25: 128894 | P25: =G25-N25-I25 -> 44074.4 | Q25: =P25/(G25-I25) -> 0.25481186 | R25: =P25+L25+M25 -> 78756.25 | S25: =R25/(G25-I25) -> 0.45532161
C26: TUV 2L | E26: 113000 | F26: 0.1724 | G26: =E26*(1-F26) -> 93518.8 | I26: =$I$16*G26 -> 4675.94 | K26: 46676.7 | L26: 16651.5 | M26: 3277.8 | N26: 66606 | P26: =G26-N26-I26 -> 22236.86 | Q26: =P26/(G26-I26) -> 0.25029428 | R26: =P26+L26+M26 -> 42166.16 | S26: =R26/(G26-I26) -> 0.47461507
C27: TUV 3L | E27: 127000 | F27: 0.1724 | G27: =E27*(1-F27) -> 105105.2 | I27: =$I$16*G27 -> 5255.26 | K27: 52621.2 | L27: 18633 | M27: 3277.8 | N27: 74532 | P27: =G27-N27-I27 -> 25317.94 | Q27: =P27/(G27-I27) -> 0.25355989 | R27: =P27+L27+M27 -> 47228.74 | S27: =R27/(G27-I27) -> 0.47299718
C28: IMP 130 T | E28: 252000 | F28: 0.1724 | G28: =E28*(1-F28) -> 208555.2 | I28: =$I$16*G28 -> 10427.76 | K28: 103533.3 | L28: 36150 | M28: 4916.7 | N28: 144600 | P28: =G28-N28-I28 -> 53527.44 | Q28: =P28/(G28-I28) -> 0.27016672 | R28: =P28+L28+M28 -> 94594.14 | S28: =R28/(G28-I28) -> 0.47744088
C29: TRANSFER | E29: 50000 | F29: 0.1724 | G29: =E29*(1-F29) -> 41380 | I29: =$I$16*G29 -> 2069 | K29: 21986.1 | L29: 7875 | M29: 1638.9 | N29: 31500 | P29: =G29-N29-I29 -> 7811 | Q29: =P29/(G29-I29) -> 0.19869757 | R29: =P29+L29+M29 -> 17324.9 | S29: =R29/(G29-I29) -> 0.4407138

Sheet Custos e Despesas Estrutura
C1: -1046700.3 | D1: -1067017.1 | E1: -932656.66 | F1: -836846.59 | G1: -824046.73 | H1: -983288.41 | R1: Considerar? | S1: (Multiple Items)
B2: Desc. | C2: 202501 | D2: 202502 | E2: 202503 | F2: 202504 | G2: 202505 | H2: 202506 | J2: Custo estrutura (sem faturamento) | K2: Método/Motivo | M2: Peças/Service + Máquinas Selecionadas | N2: Método/Motivo | O2: Somente Peças/Service | P2: Método/Motivo
B3: 3.03.01.004.00272 - Locação de Cilindros | C3: -1366.48 | D3: -1480.35 | E3: -1480.35 | F3: -1480.35 | G3: -1480.35 | H3: -1480.35 | J3: 0 | K3: Foi considerado que não é necessário nessa estrutura | M3: 0 | N3: Foi considerado que não é necessário nessa estrutura | O3: 0 | P3: Foi considerado que não é necessário nessa estrutura | R3: Sum of R$ | S3: Column Labels
B4: 3.03.01.004.00273 - Serviços de Terceiros | C4: -110879.33 | D4: -135307.16 | E4: -182526.41 | F4: -188405.52 | G4: -206748.21 | H4: -173938.95 | J4: 173938.95 | K4: 202506 | M4: 15000 | N4: 5 k ZI Manutencao + 5 k JMC Manutencao +5 k LM Manutencao | O4: 6000 | P4: 2 k ZI Manutencao + 2 k JMC Manutencao +2k LM Manutencao | R4: Row Labels | S4: 202501 | T4: 202502 | U4: 202503 | V4: 202504 | W4: 202505 | X4: 202506 | Y4: Grand Total
B5: 3.03.01.005.00275 - Depreciações | C5: -5430.09 | D5: -4897.18 | E5: -5401.23 | F5: -5227 | G5: -5401.23 | H5: -5226.98 | J5: 0 | K5: Não tem efeito caixa | M5: 0 | N5: Não tem efeito caixa | O5: 0 | P5: Não tem efeito caixa | R5: 3.03.01.004.00272 - Locação de Cilindros | S5: -1366.48 | T5: -1480.35 | U5: -1480.35 | V5: -1480.35 | W5: -1480.35 | X5: -1480.35 | Y5: -8768.23
B6: 3.03.01.005.00277 - Energia Elétrica | C6: -8625.41 | D6: -8740.24 | E6: -8497.99 | F6: -18313.15 | G6: -23194.81 | H6: -25070.01 | J6: 7703.4675 | K6: 50% Média do 1H2025 | M6: 4310.6067 | N6: 50% da média do 1T 2025 | O6: 1724.2427 | P6: 20% da média do 1T 2025 | R6: 3.03.01.004.00273 - Serviços de Terceiros | S6: -110879.33 | T6: -135307.16 | U6: -182526.41 | V6: -188405.52 | W6: -206748.21 | X6: -173938.95 | Y6: -997805.58
B7: 3.03.01.005.00279 - Água | C7: -6690.42 | D7: -5086.37 | E7: 0 | F7: -5170.48 | G7: -4336.59 | H7: -10476.68 | J7: 2646.7117 | K7: 50% Média do 1H2025 | M7: 2646.7117 | N7: 50% da média do 1H2025 | O7: 1058.6847 | P7: 20% da média do 1H2025 | R7: 3.03.01.005.00275 - Depreciações | S7: -5430.09 | T7: -4897.18 | U7: -5401.23 | V7: -5227 | W7: -5401.23 | X7: -5226.98 | Y7: -31583.71
B8: 3.03.01.006.00289 - Manutenção e Reparos | C8: -10745.3 | D8: -59302.17 | E8: -16744.2 | F8: -33301 | G8: -1817 | H8: -15641.15 | J8: 0 | K8: nulo | M8: 11462.568 | N8: 50% da média do 1H2025 | O8: 4585.0273 | P8: 20% da média do 1H2025 | R8: 3.03.01.005.00277 - Energia Elétrica | S8: -8625.41 | T8: -8740.24 | U8: -8497.99 | V8: -18313.15 | W8: -23194.81 | X8: -25070.01 | Y8: -92441.61
B9: 3.04.01.004.00314 - Depreciações | C9: -6138.22 | D9: -5723.77 | E9: -6422.11 | F9: -6357.86 | G9: -6680.91 | H9: -6465.45 | J9: 0 | K9: Não tem efeito caixa | M9: 0 | N9: Não tem efeito caixa | O9: 0 | P9: Não tem efeito caixa | R9: 3.03.01.005.00279 - Água | S9: -6690.42 | T9: -5086.37 | V9: -5170.48 | W9: -4336.59 | X9: -10476.68 | Y9: -31760.54
B10: 3.04.01.004.00315 - Aluguéis e Condomínios | C10: -101000 | D10: -17000 | E10: -17000 | F10: -37900 | G10: -65000 | H10: -56500 | J10: 0 | K10: nulo | M10: 12000 | N10: Valor estimado | O10: 5000 | P10: Valor estimado | R10: 3.03.01.006.00289 - Manutenção e Reparos | S10: -10745.3 | T10: -59302.17 | U10: -16744.2 | V10: -33301 | W10: -1817 | X10: -15641.15 | Y10: -137550.82
B11: 3.04.01.004.00316 - Energia Elétrica | C11: -48.46 | D11: -37.7 | E11: -118.63 | F11: -81.49 | G11: -57.56 | H11: -55.27 | J11: 0 | K11: Valor já considerado em outra linha | M11: 0 | N11: Valor já considerado em outra linha | O11: 0 | P11: Valor já considerado em outra linha | R11: 3.04.01.004.00314 - Depreciações | S11: -6138.22 | T11: -5723.77 | U11: -6422.11 | V11: -6357.86 | W11: -6680.91 | X11: -6465.45 | Y11: -37788.32
B12: 3.04.01.004.00317 - Telefone | C12: -8545.53 | D12: -3881.94 | E12: -6988.17 | F12: -4165.73 | G12: -9469.57 | H12: -6350.2 | J12: 3283.4283 | K12: 50% Média do 1H2025 | M12: 3283.4283 | N12: 25% da média do 1H2025 | O12: 656.68567 | P12: 20% da média do 1H2025 | R12: 3.04.01.004.00315 - Aluguéis e Condomínios | S12: -101000 | T12: -17000 | U12: -17000 | V12: -37900 | W12: -65000 | X12: -56500 | Y12: -294400
B13: 3.04.01.004.00319 - IPTU | C13: 0 | D13: 0 | E13: -30463.61 | F13: 0 | G13: 0 | H13: 0 | J13: 0 | K13: nulo | M13: 0 | N13: Já considerado no aluguel | O13: 0 | P13: Já considerado no aluguel | R13: 3.04.01.004.00316 - Energia Elétrica | S13: -48.46 | T13: -37.7 | U13: -118.63 | V13: -81.49 | W13: -57.56 | X13: -55.27 | Y13: -399.11
B14: 3.04.01.004.00426 - Amortizações | C14: -19108.04 | D14: -18638.72 | E14: -19457.28 | F14: -13612.69 | G14: -13512.48 | H14: -13193.52 | J14: 0 | K14: Não tem efeito caixa | M14: 0 | N14: Não tem efeito caixa | O14: 0 | P14: Não tem efeito caixa | R14: 3.04.01.004.00317 - Telefone | S14: -8545.53 | T14: -3881.94 | U14: -6988.17 | V14: -4165.73 | W14: -9469.57 | X14: -6350.2 | Y14: -39401.14
B15: 3.04.01.005.00320 - Correios | C15: -270.62 | D15: -901.11 | E15: -620.2 | F15: -262.16 | G15: -1300.35 | H15: -1254.76 | J15: 0 | K15: nulo | M15: 384.1 | N15: 50% da média do 1H2025 | O15: 153.64 | P15: 20% da média do 1H2025 | R15: 3.04.01.004.00319 - IPTU | U15: -30463.61 | Y15: -30463.61
B16: 3.04.01.005.00322 - Cursos | C16: 0 | D16: 0 | E16: 0 | F16: 0 | G16: 0 | H16: -3460 | J16: 0 | K16: nulo | M16: 0 | N16: Despesa considerada não essencial | O16: 0 | P16: Despesa considerada não essencial | R16: 3.04.01.004.00426 - Amortizações | S16: -19108.04 | T16: -18638.72 | U16: -19457.28 | V16: -13612.69 | W16: -13512.48 | X16: -13193.52 | Y16: -97522.73
B17: 3.04.01.005.00323 - Lanches e Refeições | C17: -4413.46 | D17: -6159.51 | E17: -16544.74 | F17: -12455.07 | G17: -7391.39 | H17: -9853.21 | J17: 4734.7817 | K17: 50% Média do 1H2025 | M17: 0 | N17: Despesa considerada não essencial | O17: 0 | P17: Despesa considerada não essencial | R17: 3.04.01.005.00320 - Correios | S17: -270.62 | T17: -901.11 | U17: -620.2 | V17: -262.16 | W17: -1300.35 | X17: -1254.76 | Y17: -4609.2
B18: 3.04.01.005.00324 - Manutenção e Reparos | C18: -25241.02 | D18: -21069.29 | E18: -24293.29 | F18: -22732.45 | G18: -22845.69 | H18: -27889.63 | J18: 0 | K18: nulo | M18: 12005.948 | N18: 50% da média do 1H2025 | O18: 4802.379 | P18: 20% da média do 1H2025 | R18: 3.04.01.005.00322 - Cursos | X18: -3460 | Y18: -3460
B19: 3.04.01.005.00325 - Limpeza e Conservação | C19: -233259.12 | D19: -135346.86 | E19: -178832.65 | F19: -121262.57 | G19: -80874.96 | H19: -63836.52 | J19: 67784.39 | K19: 50% Média do 1H2025 | M19: 19635.52 | N19: (202506 mas Sem J.O.F. SOLUCOES; sem AMB UNIFORMES; sem MDS INSTALACAO; sem ALVIN ALONSO FRANCIS; Sem SANREI INSTALACOES) | O19: 9817.76 | P19: 50% do outro cenário | R19: 3.04.01.005.00323 - Lanches e Refeições | S19: -4413.46 | T19: -6159.51 | U19: -16544.74 | V19: -12455.07 | W19: -7391.39 | X19: -9853.21 | Y19: -56817.38
B20: 3.04.01.005.00326 - Segurança | C20: -59720.15 | D20: -56657.15 | E20: -49925.41 | F20: -4550 | G20: -4550 | H20: -4550 | J20: 4550 | K20: Média do 2T 2025 | M20: 0 | N20: Despesa considerada não essencial | O20: 0 | P20: Despesa considerada não essencial | R20: 3.04.01.005.00324 - Manutenção e Reparos | S20: -25241.02 | T20: -21069.29 | U20: -24293.29 | V20: -22732.45 | W20: -22845.69 | X20: -27889.63 | Y20: -144071.37
B21: 3.04.01.005.00327 - Seguros | C21: -11018.13 | D21: -12275.4 | E21: -12453.6 | F21: -12420.54 | G21: -7689.23 | H21: -14944.21 | J21: 11684.66 | K21: Média do 2T 2025 | M21: 0 | N21: Despesa considerada não essencial | O21: 0 | P21: Despesa considerada não essencial | R21: 3.04.01.005.00325 - Limpeza e Conservação | S21: -233259.12 | T21: -135346.86 | U21: -178832.65 | V21: -121262.57 | W21: -80874.96 | X21: -63836.52 | Y21: -813412.68
B22: 3.04.01.005.00328 - Viagens e Estadias | C22: -73672.28 | D22: -66530.51 | E22: -47136.84 | F22: -84717.23 | G22: -97067.24 | H22: -56796.77 | J22: 0 | K22: nulo | M22: 5678.9449 | N22: 8% da média do 1H2025 | O22: 3549.3406 | P22: 5% da média do 1H2025 | R22: 3.04.01.005.00326 - Segurança | S22: -59720.15 | T22: -56657.15 | U22: -49925.41 | V22: -4550 | W22: -4550 | X22: -4550 | Y22: -179952.71
B23: 3.04.01.005.00330 - Impostos e Taxas | C23: -12738.67 | D23: -5945.3 | E23: -8468.41 | F23: -6717.89 | G23: -4746.26 | H23: -5029.53 | J23: 5497.8933 | K23: Média do 2T 2025 | M23: 1454.8687 | N23: 20% 202506 | O23: 1454.8687 | P23: 20% 202506 | R23: 3.04.01.005.00327 - Seguros | S23: -11018.13 | T23: -12275.4 | U23: -12453.6 | V23: -12420.54 | W23: -7689.23 | X23: -14944.21 | Y23: -70801.11
B24: 3.04.01.005.00467 - Fretes e Combustíveis | C24: -16295.1 | D24: -19560.69 | E24: -11877.87 | F24: -20399.51 | G24: -18859.26 | H24: -16883.09 | J24: 0 | K24: nulo | M24: 1385.0069 | N24: 8% da média do 1H2025 | O24: 865.62933 | P24: 5% da média do 1H2025 | R24: 3.04.01.005.00328 - Viagens e Estadias | S24: -73672.28 | T24: -66530.51 | U24: -47136.84 | V24: -84717.23 | W24: -97067.24 | X24: -56796.77 | Y24: -425920.87
B25: 3.04.01.005.00468 - Despesas com Exportação | C25: 0 | D25: -5157.18 | E25: -880 | F25: -5220 | G25: -1495 | H25: 0 | J25: 0 | K25: nulo | M25: 0 | N25: Nulo | O25: 0 | P25: Nulo | R25: 3.04.01.005.00330 - Impostos e Taxas | S25: -12738.67 | T25: -5945.3 | U25: -8468.41 | V25: -6717.89 | W25: -4746.26 | X25: -5029.53 | Y25: -43646.06
B26: 3.04.01.006.00332 - Feiras e Exposição | C26: -1540 | D26: -53913.89 | E26: -20839.51 | F26: -4920 | G26: 0 | H26: 0 | J26: 0 | K26: nulo | M26: 0 | N26: Despesa considerada não essencial | O26: 0 | P26: Despesa considerada não essencial | R26: 3.04.01.005.00467 - Fretes e Combustíveis | S26: -16295.1 | T26: -19560.69 | U26: -11877.87 | V26: -20399.51 | W26: -18859.26 | X26: -16883.09 | Y26: -103875.52
B27: 3.04.01.006.00333 - Propaganda e Publicidade | C27: 0 | D27: 0 | E27: 0 | F27: 0 | G27: 0 | H27: 0 | J27: 0 | K27: nulo | M27: 0 | N27: Despesa considerada não essencial | O27: 0 | P27: Despesa considerada não essencial | R27: 3.04.01.005.00468 - Despesas com Exportação | T27: -5157.18 | U27: -880 | V27: -5220 | W27: -1495 | Y27: -12752.18
B28: 3.04.01.006.00334 - Perdas de Duplicatas | C28: 0 | D28: 0 | E28: 0 | F28: 0 | G28: 0 | H28: 0 | J28: 0 | K28: nulo | M28: 0 | N28: Despesa considerada não essencial | O28: 0 | P28: Despesa considerada não essencial | R28: 3.04.01.006.00332 - Feiras e Exposição | S28: -1540 | T28: -53913.89 | U28: -20839.51 | V28: -4920 | Y28: -81213.4
B29: 3.04.01.006.00335 - Assessoria e Consultoria | C29: -203476.31 | D29: -217368.99 | E29: -186109.77 | F29: -175151.41 | G29: -175296.99 | H29: -170396.44 | J29: 34722.989 | K29: 20% Média do 2T 2025 | M29: 18796.665 | N29: 10% da média do 1H2025 | O29: 9398.3326 | P29: 5% da média do 1H2025 | R29: 3.04.01.006.00335 - Assessoria e Consultoria | S29: -203476.31 | T29: -217368.99 | U29: -186109.77 | V29: -175151.41 | W29: -175296.99 | X29: -170396.44 | Y29: -1127799.9
B30: 3.04.01.006.00336 - Auditoria | C30: -4722.29 | D30: -4722.29 | E30: -4722.29 | F30: -4722.29 | G30: -4722.29 | H30: -4722.29 | J30: 4722.29 | K30: Média do 2T 2025 | M30: 4722.29 | N30: 202506 | O30: 4722.29 | P30: 202506 | R30: 3.04.01.006.00336 - Auditoria | S30: -4722.29 | T30: -4722.29 | U30: -4722.29 | V30: -4722.29 | W30: -4722.29 | X30: -4722.29 | Y30: -28333.74
B31: 3.04.01.006.00337 - Honorários Advocatícios | C31: -10900 | D31: -10900 | E31: -10900 | F31: -10900 | G31: -10900 | H31: -10900 | J31: 10900 | K31: Média do 2T 2025 | M31: 1090 | N31: 10% da média do 1H2025 | O31: 545 | P31: 5% da média do 1H2025 | R31: 3.04.01.006.00337 - Honorários Advocatícios | S31: -10900 | T31: -10900 | U31: -10900 | V31: -10900 | W31: -10900 | X31: -10900 | Y31: -65400
B32: 3.04.01.006.00338 - Assinaturas Jornais e Revistas | C32: -513.09 | D32: -513.09 | E32: -513.09 | F32: -513.09 | G32: -524.19 | H32: -524.19 | J32: 520.49 | K32: Média do 2T 2025 | M32: 0 | N32: Despesa considerada não essencial | O32: 0 | P32: Despesa considerada não essencial | R32: 3.04.01.006.00338 - Assinaturas Jornais e Revistas | S32: -513.09 | T32: -513.09 | U32: -513.09 | V32: -513.09 | W32: -524.19 | X32: -524.19 | Y32: -3100.74
B33: 3.04.01.006.00339 - Fotocópias e Reproduções | C33: 0 | D33: 0 | E33: 0 | F33: 0 | G33: 0 | H33: 0 | J33: 0 | K33: nulo | M33: 0 | N33: Despesa considerada não essencial | O33: 0 | P33: Despesa considerada não essencial | R33: 3.04.01.006.00340 - Materiais de Escritório | S33: -14391.63 | T33: -11692.02 | U33: -13476.57 | V33: -5521.91 | W33: -5012.01 | X33: -4299.87 | Y33: -54394.01
B34: 3.04.01.006.00340 - Materiais de Escritório | C34: -14391.63 | D34: -11692.02 | E34: -13476.57 | F34: -5521.91 | G34: -5012.01 | H34: -4299.87 | J34: 4532.8342 | K34: 50% Média do 1H2025 | M34: 906.56683 | N34: 10% da média do 1H2025 | O34: 453.28342 | P34: 5% da média do 1H2025 | R34: 3.04.01.006.00341 - Donativos e Contribuições | S34: -4169.16 | T34: -4169.16 | U34: -12969.46 | V34: -2891.15 | W34: -6926.49 | X34: -9671.84 | Y34: -40797.26
B35: 3.04.01.006.00341 - Donativos e Contribuições | C35: -4169.16 | D35: -4169.16 | E35: -12969.46 | F35: -2891.15 | G35: -6926.49 | H35: -9671.84 | J35: 3399.7717 | K35: Média do 1H2025 | M35: 3399.7717 | N35: 50% da média do 1H2025 | O35: 1359.9087 | P35: 20% da média do 1H2025 | R35: 3.04.01.006.00342 - Estacionamento | S35: -15 | X35: -29 | Y35: -44
B36: 3.04.01.006.00342 - Estacionamento | C36: -15 | D36: 0 | E36: 0 | F36: 0 | G36: 0 | H36: -29 | J36: 0 | K36: nulo | M36: 0 | N36: Despesa considerada não essencial | O36: 0 | P36: Despesa considerada não essencial | R36: 3.04.01.006.00343 - Cartórios e Tabelionatos | S36: -189.44 | Y36: -189.44
B37: 3.04.01.006.00343 - Cartórios e Tabelionatos | C37: -189.44 | D37: 0 | E37: 0 | F37: 0 | G37: 0 | H37: 0 | J37: 0 | K37: nulo | M37: 0 | N37: Despesa considerada não essencial | O37: 0 | P37: Despesa considerada não essencial | R37: 3.04.01.006.00345 - Multas Fiscais | S37: -54041.93 | T37: -81815.14 | X37: -215776.07 | Y37: -351633.14
B38: 3.04.01.006.00344 - Custas Judiciais | C38: 0 | D38: 0 | E38: 0 | F38: 0 | G38: 0 | H38: 0 | J38: 0 | K38: nulo | M38: 0 | N38: Despesa considerada não essencial | O38: 0 | P38: Despesa considerada não essencial | R38: 3.04.01.006.00346 - Despesas Indedutíveis | S38: -2677.96 | T38: -2560.67 | U38: -1720.7 | V38: -2218.05 | W38: -4974.23 | X38: -1355.21 | Y38: -15506.82
B39: 3.04.01.006.00345 - Multas Fiscais | C39: -54041.93 | D39: -81815.14 | E39: 0 | F39: 0 | G39: 0 | H39: -215776.07 | J39: 0 | K39: nulo | M39: 0 | N39: Nulo | O39: 0 | P39: Nulo | R39: 3.04.01.007.00411 - Prejuízo na Venda de Bens | V39: 0 | X39: 0 | Y39: 0
